Workbook
Name Text1: #REF!
Name Text2: #REF!

Sheet Instructions
B3: Instructions
A5: 1) | B5: Complete both the Completion Checklist and Scoring tabs in this workbook.
B7: a) | C7: If this is Year 1 in the two-year NOFA cycle, use the Scoring - New App tab (hide/unhide tabs as needed)
B8: b) | C8: If this is Year 2 in the two-year NOFA cycle, use the Scoring - Renewal App tab (hide/unhide tabs as needed)
A10: 2) | B10: Only cells in blue need to be filled, other cells will autopopulate.
B15: Formulas
B16: Yes
B17: No

Sheet Completion Checklist
B1: DEPARTMENT OF HOUSING | I1: FY2021-2022 NOFA Review
B2: Public Service Scoring Sheet
B4: Project Information
D5: Public Services; Fair Housing; Micro-Enterprise Activities; Non-Profit Administered Minor Home Repair Programs Grants
C8: Applicant: | F8: Reviewed by:
C9: Project: | F9: Review Date:
C10: Amount Requested:
C11: Total Project Cost:
B14: Threshold Criteria
B16: NON-PROFIT ORGANIZATIONAL DOCUMENTS/ NOTES
C17: Resolution
D18: Authorizing Application Submission
D19: Designating Person to Execute County Agt(s)
C20: Non-Profit Status - Date of IRS Letter:________
C21: Corporate By-laws
C22: Articles of Incorporation
C23: Board Roster
D24: List of Board Directors
C25: Board Dates (the last 12 months)
C26: Organizational Chart
C27: Audit Year Submitted: _________
D28: Single Audit
D29: Certification Letter (did not spend over $750,000 fed.)
C30: Debarment check www.sam.gov
B34: Application Documents
C35: Application
C36: A-1 Current Agency Operating Budget
B41: Publ

Sheet Scoring - New App
B1: DEPARTMENT OF HOUSING | I1: ='Completion Checklist'!I1 -> FY2021-2022 NOFA Review
B2: Public Service Scoring Sheet
B4: Project Information
D5: Public Services; Fair Housing; Micro-Enterprise Activities; Non-Profit Administered Minor Home Repair Programs Grants
C8: Applicant: | E8: ='Completion Checklist'!E8 -> 0 | F8: Reviewed by: | G8: ='Completion Checklist'!G8 -> 0
C9: Project: | E9: ='Completion Checklist'!E9 -> 0 | F9: Review Date: | G9: ='Completion Checklist'!G9 -> 0
C10: Amount Requested: | E10: ='Completion Checklist'!E10 -> 0
C11: Total Project Cost: | E11: ='Completion Checklist'!E11 -> 0
C13: Summary
C14: Score: | F14: =I51+I57+I62+I70+I75 -> #DIV/0!
C15: Recommendation for Project Funding: | F15: =F89 -> 0
C16: Funding Recommendation Summary Comments: | F16: =B92 -> 0
B18: Threshold Criteria
B21: A) | C21: Threshold Criteria (Yes/No) | F21: Comments:
D22: Application received on time
D23: Application complete
D24: Project is eligible for CDBG, HOME or ESG funding
D25: Project applicant is in good standing
D26: Satisfactory performance in meeting project goals
D27: Timely submission of all required documentation
D28: No unresolved monitoring findings
B30: B) | C30: Application meets CDBG national objective of Benefit to Low Income Persons/Households (Check Appropriate Box):
D31: Services to Presumed Benefit Group:
D32: Services to Low Income (General)
D33: Removal of architectural barriers to seniors/severely disabled adults
D34: Minor home repairs
B36: C) | C36: How will applicant verify client income/presumed benefit status?
B40: Scoring
B42: Instructions to Reviewer: Please provide a score of 0, 1, 2 or 3 for each element within the overall criteria. The total score for each criterion is an average of all the sub-scores. Please explain any score of 0 or 1 in the comment section. Maximum score is 15.
B51: 1) | D51: Funding Priority | G51: Comments | H51: Score: | I51: =AVERAGE(H52:I55) -> #DIV/0!
B52: a. | D52: What priority does project meet or need?
B53: b. | D53: Who is program targeting?
B54: c. | D54: What is applicant proposing?
B55: d. | D55: Specific role?
B57: 2) | D57: Sponsor Capacity / Capabilities | G57: Comments | H57: Score: | I57: =AVERAGE(H58:I60) -> #DIV/0!
B58: a. | D58: What is experience of applicant in performing proposed services?
B59: b. | D59: What is applicant’s ability to measure the need/impact of services?
B60: c. | D60: Is organization fiscally and programmatically stable? How so?
B62: 3) | D62: Project Feasibility/Readiness | G62: Comments | H62: Score: | I62: =AVERAGE(H63:I68) -> #DIV/0!
B63: a. | D63: Is this an on-going program already in existence or a new program? (see scoring rubric)
...

Sheet Scoring - New Application
B1: DEPARTMENT OF HOUSING | I1: ='Completion Checklist'!I1 -> FY2021-2022 NOFA Review
B2: Public Service Scoring Sheet
B4: Project Information
D5: Public Services; Fair Housing; Micro-Enterprise Activities; Non-Profit Administered Minor Home Repair Programs Grants
C8: Applicant: | E8: ='Completion Checklist'!E8 -> 0 | F8: Reviewed by: | G8: ='Completion Checklist'!G8 -> 0
C9: Project: | E9: ='Completion Checklist'!E9 -> 0 | F9: Review Date: | G9: ='Completion Checklist'!G9 -> 0
C10: Amount Requested: | E10: ='Completion Checklist'!E10 -> 0
C11: Total Project Cost: | E11: ='Completion Checklist'!E11 -> 0
C13: Summary
C14: Score: | F14: =I42+I48+I53+I61+I66 -> #DIV/0!
C15: Recommendation for Project Funding: | F15: =F80 -> 0
C16: Funding Recommendation Summary Comments: | F16: =B83 -> 0
B18: Threshold Criteria
B21: A) | C21: Threshold Criteria (Yes/No) | F21: Comments:
D22: Application received on time
D23: Application complete
D24: Project is eligible for CDBG, HOME or ESG funding
D25: Project applicant is in good standing
D26: Satisfactory performance in meeting project goals
D27: Timely submission of all required documentation
D28: No unresolved monitoring findings
B31: Scoring
B33: Instructions to Reviewer: Please provide a score of 0, 1, 2 or 3 for each element within the overall criteria. The total score for each criterion is an average of all the sub-scores. Please explain any score of 0 or 1 in the comment section. Maximum score is 15.
B42: 1) | D42: Funding Priority | G42: Comments | H42: Score: | I42: =AVERAGE(H43:I46) -> #DIV/0!
B43: a. | D43: What priority does project meet or need?
B44: b. | D44: Who is program targeting?
B45: c. | D45: What is applicant proposing?
B46: d. | D46: Specific role?
B48: 2) | D48: Sponsor Capacity / Capabilities | G48: Comments | H48: Score: | I48: =AVERAGE(H49:I51) -> #DIV/0!
B49: a. | D49: What is experience of applicant in performing proposed services?
B50: b. | D50: What is applicant’s ability to measure the need/impact of services?
B51: c. | D51: Is organization fiscally and programmatically stable? How so?
B53: 3) | D53: Project Feasibility/Readiness | G53: Comments | H53: Score: | I53: =AVERAGE(H54:I59) -> #DIV/0!
B54: a. | D54: Is this an on-going program already in existence or a new program? (see scoring rubric)
B55: b. | D55: If new, when will program operations begin? (see scoring rubric)
B56: c. | D56: If on-going program or continuing application, what is history of CDBG funding for this program?
B57: d. | D57: How will program be administered? Outreach? Any partnerships/collaborations with other agencies?
B58: e. | D58: Any issues with this program?
B59: f. | D59: Any unique, innovative, unusual or complex aspects in proposal?
B61: 4) | D61: Cost Effectiveness | G61: Comments | H61: Score: | I61: =AVERAGE(H62:I64) -> #DIV/0!
...

Sheet App Checklist - Doc Review
A1: DEPARTMENT OF HOUSING | D1: Document Review Sheet | G1: FY2026-27 NOFA Review
A2: Reviewer Name: | F2: Text Key
A3: Date Reviewed: | F3: Utilize Red text, Orange text, or Black text in Column 'H' to flag any notes or comments
A4: Applicant Name: | F4: Item Missing or Issue with Submitted Document
A5: Project Name: | F5: Possible Issue with Document
A6: Applicant Type (Non-Profit, Public Entity): | F6: General Notes
A7: Attachments | E7: Included? (Yes/No) | F7: Instructions for Document Review | H7: Comments or Concerns to Note
A8: Make sure updated documents are attached
A9: 1.) Resolution authorizing application and designation of signatory, by the Board of Directors
A10: Authorizing Application Submission | F10: This can be one or two separate resolutions. Must state they are allowed to apply and who can sign the agreement.
A11: Designating Person to Execute County Agreements
A12: 2.) Proof of 501(c)3 / tax-exempt status (Non-Profit Status) | F12: Type in EIN # here:
A13: 3.) By-laws | F13: Organization, Non-Profit; or City by-laws.
A14: 4.) Articles of Incorporation | F14: Confirm the organization's name on the document.
A15: 5.) Board Roster - including the following: | F15: Board of Directors information (Names, roles, etc)
A16: Name, Company, Years on Board
A17: Meeting dates for previous 12 months
A18: Number of years allowed for each Board Term
A19: 6.) Organizational chart for the entire organization (not just the project) | F19: Staff name and roles should be identifiable. Okay to have just position roles due to staff turnover.
A20: 7.) Financial Documents | F20: Review Slide #7 for example: Funding Team 1.5.26
A21: Certified financial audit no more than one (1) fiscal year old, prepared by a CPA
A22: Management letters
A23: 8.) Federal Single Audit: 2 CFR Part 200, Subpart F Single Audit (for entities that expend more than $1M in Federal funding) | F23: Document must be dated after July 1, 2024 or the organization must submit another form of proof (e.g., cover letter, explanation, etc.).
F24: Review Slide #8 for example: Funding Team 1.5.26
A25: OR a letter from the Executive Director or Corporate Financial Officer certifying that agency does not expend more than $1M in Federal funds and is not subject to the Single Audit Requirement. (i.e., Cert for No Single Audit) | F25: Exhibit 2 - 'Cert for No Single Audit' doc completed, signed and submitted?
A26: Audit Rev. comments | F26: List all audit comments (if any) in Column H in Black text.
A27: 9.) Budgets | F27: Check for completeness of 'Proposed Program Budget for FY 2026-27' Table in application (after item #20) and compare to attachment.
A28: Current (FY25-26) Agency Operating Budget
A29: Proposed (FY26-27) Agency Operating Budget
A30: Current (FY25-26) Program Operating Budget
A31: 10.) Mission Statement
A32: 11.) Non-discrimination policy for Staff and Clients
A33: 12.) Reasonable Accommodations Policy for Staff and Clients
A34: 13.) Conflict of Interest Policy
A35: 14.) Negotiated Rate Letter (if applicable)
A36: 15.) Required Exhibits (For all SMC Apps)
A37: Exhibit 5: Governing Body Description | F37: Exhibit 5 attachment should address the 5 questions listed in Page #21 in the Comm Dev NOFA Guideline.
A38: Exhibit 6: Position Bios | F38: Exhibit 6 attachment should address the 'Requested Information' listed in Page #22 in the Comm Dev NOFA Guideline.
A39: Exhibit 7: Sample Attestation of Financial Compliance | F39: Exhibit 7 attachment should be completed and signed with sample language provided in Page #23 in the Comm Dev NOFA Guideline.
A40: 16.) Other | F40: Please list name of document/attachments submitted (if applicable) in Column H Black text.
...

Sheet Threshold+Scoring - Reviewer 1
B1: DEPARTMENT OF HOUSING | G1: FY2026-27 NOFA REVIEW
B2: Public Services Scoring Sheet
B4: PROJECT INFORMATION
D5: Public Services; Fair Housing; Micro-Enterprise Activities
C8: Applicant: | F8: Reviewed By:
C9: Project: | F9: Review Date:
C10: Amount Requested: | E10: ='Completion Checklist'!E10 -> 0
C11: Total Project Cost: | E11: ='Completion Checklist'!E11 -> 0
C12: Total Clients Served: | E12: 0 | F12: Use number of households
C14: Project Description: Include the Priority Need being Addressed
C17: Recommendation Summary
C18: Total Score: | F18: =SUM(H64,H65,H68,H69,H70,H71,H74,H75,H76,H77,H78,H80,H85,H86,H87) -> 0
C19: Recommendation for Project Funding (Yes or No):
C20: Recommended Funding Source: CDBG for Fair Housing, and everything else except shelters and rapid rehousing (RRH), which are funded by ESG
C21: Funding Recommendation Summary Comments: Please note any concerns, proposal deficiencies, proposal highlights, etc.
B25: Threshold Criteria
B28: A) | C28: Threshold Criteria (Toggle Yes/No) | F28: Comments:
C29: Yes | D29: Application received on time | F29: All applications to be reviewed meet this threshold criteria
C30: No | D30: Submitted by an eligible applicant for an eligible activity
D31: Application complete
D32: Are they open to receiving State/Federal ESG or PLHA funding instead of CDBG?
D33: Satisfactory performance in meeting project goals
D34: Timely submission of all required documentation | F34: Within 48 hours of emailed request
B36: B) | C36: Application Documents | G36: Included? (Yes/No)
C37: Are all fields filled in and complete?
C38: If not, note which items are missing or are incomplete
C39: 1.
C40: 2.
C41: 3.
B43: C) | C43: Does the application meet CDBG national objective of Benefit to Low Income Persons/Households (Check Appropriate Box):
D44: Services to Presumed Benefit Group (definition at right): | F44: Target population(s): | I44: Presumed Benefit groups: abused children, battered spouses, elderly persons, severely disabled adults, homeless persons, illiterate adults, persons living with AIDS and migrant farm workers
D45: Does the project focus on persons experiencing homelessness and/or ELI individuals (≤30% AMI)?
D46: Services to Low Income (General)
D47: Improvement is limited to removal of architectural barriers to seniors (62+)/severely disabled adults
D48: Minor Home Repairs | F48: East Palo Alto? YES / NO
D49: Fair Housing
B50: D) | C50: How will applicant verify client income/presumed benefit status? (please note in your Comments on Row 21 if they plan on using self-certification)
B53: Scoring
B55: Instructions to Reviewer: Please provide a score of 0, 1, 2 or 3 for each element within the overall criteria. The total score for each criterion is an average of all the sub-scores. Maximum score is 15.
D57: Scoring Key
...

Sheet Scoring Sheet - Reviewer 2
B1: DEPARTMENT OF HOUSING | G1: FY2026-27 NOFA REVIEW
B2: Public Services Scoring Sheet
B4: PROJECT INFORMATION
D5: Public Services; Fair Housing; Micro-Enterprise Activities
C8: Applicant: | F8: Reviewed By:
C9: Project: | F9: Review Date:
C10: Amount Requested: | E10: ='Completion Checklist'!E10 -> 0
C11: Total Project Cost: | E11: ='Completion Checklist'!E11 -> 0
C12: Total Clients Served: | E12: 0 | F12: Use number of households
C14: Project Description: Include the Priority Need being Addressed
C17: Recommendation Summary
C18: Total Score: | F18: =SUM(H36,H37,H40,H41,H42,H43,H46,H47,H48,H49,H50,H52,H57,H58,H59) -> 0
C19: Recommendation for Project Funding (Yes or No):
C20: Recommended Funding Source: CDBG for Fair Housing, and everything else except shelters and rapid rehousing (RRH), which are funded by ESG
C21: Funding Recommendation Summary Comments: Please note any concerns, proposal deficiencies, proposal highlights, etc.
B25: Scoring
B27: Instructions to Reviewer: Please provide a score of 0, 1, 2 or 3 for each element within the overall criteria. The total score for each criterion is an average of all the sub-scores. Maximum score is 15.
D29: Scoring Key
D30: 0 | E30: Below Standard - Does not meet basic requirements | G30: Please explain any score of 0 or 1 in the Comments section on Row 21.
D31: 1 | E31: Weak - Lacks vital information (please note what is lacking)
D32: 2 | E32: Satisfactory - Meets basic requirements
D33: 3 | E33: Strong - Exceeds basic requirements
A35: 1) | D35: Funding Priority (click link to review) | G35: Comments | H35: Score: | I35: NOTES ABOUT SCORING
B36: a. | D36: Which County priority does project meet or need? | I36: 0 - The project does not meet a County priority. 3 - The project does meet a County priority.
B37: b. | D37: What population is the program targeting? | I37: 3 for ELI 2 for ELI to VLI 1 for VLI to Moderate 0 for moderate income
A39: 2) | D39: Applicant / Sponsor Capacity and Capabilities | G39: Comments | H39: Score:
B40: a. | D40: What is experience/capacity of applicant in performing and undertaking proposed services/work? (Application Response to #14) | I40: 0 if they have no demonstrated positive outcomes (i.e., housing homeless clients) with this type of project/work or have missed performance targets by more than 50% in previous County funded projects 1 or 2 if they have demonstrated positive outcomes with related work or if they have met 50-75% of performance targets in previous projects; New applicants will likely be scored at 1 or 2. 3 if they have a demonstrated positive outcomes with this exact project type and have met 75%+ performance targets
B41: b. | D41: What is applicant’s ability to measure the need/impact of services? | I41: 0 if they have no process/ability 1 or 2 if they have some 3 if they have a very well defined process/ability
B42: c. | D42: What is the applicant's ability to complete administrative requirements (e.g., QPRs, CDS / HMIS data entry)? | I42: 0 if they have no direct or related experience 1 if they have direct experience that is not good or if they have related experience 2 if they have direct experience that is OK 3 if they have direct and positive experience
B43: d. | D43: Is organization fiscally and programmatically stable? How so? (Review Exhibit 7 in the NOFA.) | I43: 0 if there are concerns in their audit 1 or 2 if they seem to be operating based on their reserves 3 if their income matches or exceeds annual expenses
A45: 3) | D45: Project Feasibility/Readiness | G45: Comments | H45: Score:
B46: a. | D46: Is this an on-going program already in existence or a new program? | I46: 0 if not yet launched 1 if launched within past 3 months 2 if launched within past 6 months 3 if launched 7+ months ago
B47: b. | D47: If new, when will program operations begin? | I47: 0 if it will start after Oct 1, 2026 1 if it will start by Sep 1, 2026 2 if it will start by Aug 15, 2026 3 if it will start by July 2026 or is an ongoing project
B48: c. | D48: If this is an on-going program or continuing application, have they received CDBG / County funding for this program in the past? | I48: 0 if they have never received County support of any kind 1 if they have received local support from a city 2 if they have received federal support from another city/county 3 if they have received San Mateo County support
B49: d. | D49: How will program be administered? Outreach? Any partnerships/collaborations with other agencies? | I49: 0 if done alone 1 or 2 if done in partnership/collaboration with at least 1-2 other entities 3 if done with an ecosystem of partners/collaborators
B50: e. | D50: Are there any unique, unusual or complex features/elements in the proposal, which may impede its success (score as 0 or 1) and/or will contribute to its success/impact (score as 2 or 3)?
A51: 4) | D51: Cost Effectiveness | G51: Comments | H51: Score:
B52: a. | D52: Is total unit cost of service (service cost per household served) reasonable? This is somewhat subjective/project specific. | I52: 0 if it does not seem reasonable 3 if it seems very reasonable *Please use comments to explain your rating.
B53: b. | D53: How was costing done? (SMC only section, Response to #2) | H53: XX | I53: For reference only, not scored | L53: Review the total number of people served by the entire program. Did the applicant provide a thorough narrative that explains their costing methodology?
A55: 5) | D55: Leveraging | G55: Comments | H55: Score:
...
